package top.woilanlan.exceptions;

/**
 * 重新抛出异常
 * 使用 fillInStackTrace()
 */
public class Rethrowing {

    public static void f() throws Exception {
        System.out.println("originating the exception in f()");
        throw new Exception("thrown from f()");
    }

    public static void g() throws Exception {
        try {
            f();
        } catch (Exception e) {
            System.out.println("Inside g(),e.printStackTrace()");
            e.printStackTrace(System.out);
            throw e;
        }
    }

    public static void h() throws Exception {
        try {
            f();
        } catch (Exception e) {
            System.out.println("Inside h(),e.printStackTrace()");
            e.printStackTrace(System.out);
            // 把当前调用栈信息填入原来的异常对象并返回，
            // 这一行成了异常的新发生地
            throw (Exception) e.fillInStackTrace();
        }
    }

    public static void show() {
        try {
            g();
        } catch (Exception e) {
            System.out.println("main: printStackTrace()");
            e.printStackTrace(System.out);
        }
        try {
            h();
        } catch (Exception e) {
            System.out.println("main: printStackTrace()");
            e.printStackTrace(System.out);
        }
    }
}
